Workbook

Sheet період
A1: Територіальний розріз | B1: Розріз | C1: Вид господарства | D1: Період | E1: Виробництво, тис. т | F1: Дата
A2: Україна | B2: Молоко | C2: Господарства населення | D2: Січ.-жов. 2025 | E2: 3229.3 | F2: 45931
A3: Україна | B3: Молоко | C3: Господарства населення | D3: Січ.-лис. 2025 | E3: 3470.3 | F3: 45962
A4: Івано-Франківська | B4: Молоко | C4: Підприємства | D4: Січ.-жов. 2025 | E4: 14.1 | F4: 45931
A5: Вінницька | B5: Молоко | C5: Підприємства | D5: Січ.-лис. 2025 | E5: 263.3 | F5: 45962
A6: Івано-Франківська | B6: Молоко | C6: Господарства населення | D6: Січ.-жов. 2025 | E6: 185.9 | F6: 45931
A7: Івано-Франківська | B7: Молоко | C7: Господарства населення | D7: Січ.-лис. 2025 | E7: 200.8 | F7: 45962
A8: Луганська | B8: Молоко | C8: Господарства населення | D8: Січ.-жов. 2025 | E8: 0 | F8: 45931
A9: Луганська | B9: Молоко | C9: Господарства населення | D9: Січ.-лис. 2025 | E9: 0 | F9: 45962
A10: Донецька | B10: Молоко | C10: Господарства усіх категорій | D10: Січ.-жов. 2025 | E10: 14.9 | F10: 45931
A11: Донецька | B11: Молоко | C11: Господарства усіх категорій | D11: Січ.-лис. 2025 | E11: 16.2 | F11: 45962
A12: Дніпропетровська | B12: Молоко | C12: Підприємства | D12: Січ.-жов. 2025 | E12: 53.1 | F12: 45931
A13: Волинська | B13: Молоко | C13: Підприємства | D13: Січ.-лис. 2025 | E13: 110.8 | F13: 45962
... A154: Україна | B154: Молоко | C154: Господарства населення | D154: Січ.-лис. 2024 | E154: 3990.0495 | F154: 45597
A155: Україна | B155: Молоко | C155: Господарства усіх категорій | D155: Січ.-жов. 2024 | E155: 6148.9 | F155: 45566 | H155: 2952.1
A156: Україна | B156: Молоко | C156: Підприємства | D156: Січ.-жов. 2024 | E156: 2462.4 | F156: 45566 | H156: 4260.6
A157: Україна | B157: Молоко | C157: Господарства населення | D157: Січ.-жов. 2024 | E157: 3686.5 | F157: 45566
A158: Вінницька | B158: Молоко | C158: Господарства усіх категорій | D158: Січ.-лис. 2024 | E158: 533 | F158: 45597
A159: Волинська | B159: Молоко | C159: Господарства усіх категорій | D159: Січ.-лис. 2024 | E159: 255 | F159: 45597
A160: Дніпропетровська | B160: Молоко | C160: Господарства усіх категорій | D160: Січ.-лис. 2024 | E160: 193 | F160: 45597
A161: Донецька | B161: Молоко | C161: Господарства усіх категорій | D161: Січ.-лис. 2024 | E161: 26 | F161: 45597
A162: Житомирська | B162: Молоко | C162: Господарства усіх категорій | D162: Січ.-лис. 2024 | E162: 384 | F162: 45597
A163: Закарпатська | B163: Молоко | C163: Господарства усіх категорій | D163: Січ.-лис. 2024 | E163: 223 | F163: 45597
A164: Запорізька | B164: Молоко | C164: Господарства усіх категорій | D164: Січ.-лис. 2024 | E164: 16 | F164: 45597
A165: Івано-Франківська | B165: Молоко | C165: Господарства усіх категорій | D165: Січ.-лис. 2024 | E165: 288 | F165: 45597
A166: Київська | B166: Молоко | C166: Господарства усіх категорій | D166: Січ.-лис. 2024 | E166: 303 | F166: 45597
A167: Кіровоградська | B167: Молоко | C167: Господарства усіх категорій | D167: Січ.-лис. 2024 | E167: 245 | F167: 45597
A168: Луганська | B168: Молоко | C168: Господарства усіх категорій | D168: Січ.-лис. 2024 | E168: 48 | F168: 45597
... A242: Україна | B242: Молоко | C242: Господарства усіх категорій | D242: Січ.-гру. 2024 | E242: 7212.7 | F242: 45627
A243: Запорізька | B243: Молоко | C243: Господарства населення | D243: Січ.-гру. 2024 | E243: 2952.1 | F243: 45627 | G243: 2952.1
A244: Дніпропетровська | B244: Молоко | C244: Господарства населення | D244: Січ.-гру. 2024 | E244: 4260.6 | F244: 45627 | G244: 4260.6
A245: Вінницька | B245: Молоко | C245: Господарства населення | D245: Січ.-гру. 2024 | E245: 316.3 | F245: 45627
A246: Донецька | B246: Молоко | C246: Господарства населення | D246: Січ.-гру. 2024 | E246: 0 | F246: 45627
A247: Полтавська | B247: Молоко | C247: Господарства усіх категорій | D247: Січ.-гру. 2024 | E247: 667.9 | F247: 45627
A248: Чернівецька | B248: Молоко | C248: Господарства населення | D248: Січ.-гру. 2024 | E248: 198.7 | F248: 45627
A249: Херсонська | B249: Молоко | C249: Підприємства | D249: Січ.-гру. 2024 | E249: 0 | F249: 45627
A250: Тернопільська | B250: Молоко | C250: Підприємства | D250: Січ.-гру. 2024 | E250: 188.2 | F250: 45627
A251: Полтавська | B251: Молоко | C251: Підприємства | D251: Січ.-гру. 2024 | E251: 445.2 | F251: 45627
A252: Тернопільська | B252: Молоко | C252: Господарства усіх категорій | D252: Січ.-гру. 2024 | E252: 513.3 | F252: 45627
A253: Хмельницька | B253: Молоко | C253: Господарства населення | D253: Січ.-гру. 2024 | E253: 399 | F253: 45627
...

Sheet місяць
A1: Територіальний розріз | B1: Розріз | C1: Вид господарства | D1: Період | E1: Виробництво, тис. т | F1: Дата
A2: Україна | B2: Молоко | C2: Господарства усіх категорій | D2: 45597 | E2: 534.6 | F2: 45597
A3: Україна | B3: Молоко | C3: Підприємства | D3: 45597 | E3: 231.0505 | F3: 45597
A4: Україна | B4: Молоко | C4: Господарства населення | D4: 45597 | E4: 303.5495 | F4: 45597
A5: Україна | B5: Молоко | C5: Господарства усіх категорій | D5: 45931 | E5: 567.5 | F5: 45931
A6: Україна | B6: Молоко | C6: Підприємства | D6: 45931 | E6: 264.3 | F6: 45931
A7: Україна | B7: Молоко | C7: Господарства населення | D7: 45931 | E7: 303.2 | F7: 45931
A8: Україна | B8: Молоко | C8: Господарства усіх категорій | D8: 45962 | E8: 506.6 | F8: 45962
A9: Україна | B9: Молоко | C9: Підприємства | D9: 45962 | E9: 265.6 | F9: 45962
A10: Україна | B10: Молоко | C10: Господарства населення | D10: 45962 | E10: 241 | F10: 45962
A11: Україна | B11: Молоко | C11: Господарства усіх категорій | D11: 45992 | E11: 477.7 | F11: 45992
A12: Україна | B12: Молоко | C12: Підприємства | D12: 45992 | E12: 271.3 | F12: 45992
A13: Україна | B13: Молоко | C13: Господарства населення | D13: 45992 | E13: 206.4 | F13: 45992
... A70: Україна | B70: Молоко | C70: Господарства населення | D70: 46266 | E70: 243 | F70: 46266

Sheet Лист1
A1: Територіальний розріз | B1: Розріз | C1: Вид господарства | D1: =E$16 -> 46266 | E1: =E$17 -> 46235 | F1: =E$18 -> 45901 | G1: 26/26 | H1: =G$1 -> 26/26 | J1: 26/25 | K1: =J$1 -> 26/25 | AA1: ="Січ.-"& CHOOSE(MOD(ROW()-ROW($A$1),12)+1, "січ.","лют.","бер.","кві.","тра.","чер.", "лип.","сер.","вер.","жов.","лис.","гру.") &" "&(2024+INT((ROW()-ROW($A$1))/12)) -> Січ.-січ. 2024 | AB1: =DATE(2024,1,1) -> 45292
A2: Україна | B2: Молоко | C2: Господарства усіх категорій | D2: =SUMIFS(місяць!$E$2:$E$4687,місяць!$A$2:$A$4687,A2,місяць!$B$2:$B$4687,B2,місяць!$C$2:$C$4687,C2,місяць!$D$2:$D$4687,Лист1!$D$1) -> 509.4 | E2: =SUMIFS(місяць!$E$2:$E$4687,місяць!$A$2:$A$4687,A2,місяць!$B$2:$B$4687,B2,місяць!$C$2:$C$4687,C2,місяць!$D$2:$D$4687,Лист1!$E$1) -> 543.7 | F2: =SUMIFS(місяць!$E$2:$E$4687,місяць!$A$2:$A$4687,A2,місяць!$B$2:$B$4687,B2,місяць!$C$2:$C$4687,C2,місяць!$D$2:$D$4687,Лист1!$F$1) -> 612.8 | G2: =D2-E2 -> -34.3 | H2: =(D2/E2)-1 -> -0.063086261 | J2: =D2-F2 -> -103.4 | K2: =(D2/F2)-1 -> -0.16873368 | AA2: ="Січ.-"& CHOOSE(MOD(ROW()-ROW($A$1),12)+1, "січ.","лют.","бер.","кві.","тра.","чер.", "лип.","сер.","вер.","жов.","лис.","гру.") &" "&(2024+INT((ROW()-ROW($A$1))/12)) -> Січ.-лют. 2024 | AB2: =DATE(YEAR(AB1),MONTH(AB1)+1,1) -> 45323
A3: Україна | B3: Молоко | C3: Підприємства | D3: =SUMIFS(місяць!$E$2:$E$4687,місяць!$A$2:$A$4687,A3,місяць!$B$2:$B$4687,B3,місяць!$C$2:$C$4687,C3,місяць!$D$2:$D$4687,Лист1!$D$1) -> 266.4 | E3: =SUMIFS(місяць!$E$2:$E$4687,місяць!$A$2:$A$4687,A3,місяць!$B$2:$B$4687,B3,місяць!$C$2:$C$4687,C3,місяць!$D$2:$D$4687,Лист1!$E$1) -> 275.7 | F3: =SUMIFS(місяць!$E$2:$E$4687,місяць!$A$2:$A$4687,A3,місяць!$B$2:$B$4687,B3,місяць!$C$2:$C$4687,C3,місяць!$D$2:$D$4687,Лист1!$F$1) -> 278.8 | G3: =D3-E3 -> -9.3 | H3: =(D3/E3)-1 -> -0.033732318 | J3: =D3-F3 -> -12.4 | K3: =(D3/F3)-1 -> -0.044476327 | M3: Підприємства | N3: =D3/D2*100% -> 0.5229682 | AA3: ="Січ.-"& CHOOSE(MOD(ROW()-ROW($A$1),12)+1, "січ.","лют.","бер.","кві.","тра.","чер.", "лип.","сер.","вер.","жов.","лис.","гру.") &" "&(2024+INT((ROW()-ROW($A$1))/12)) -> Січ.-бер. 2024 | AB3: =DATE(YEAR(AB2),MONTH(AB2)+1,1) -> 45352
A4: Україна | B4: Молоко | C4: Господарства населення | D4: =SUMIFS(місяць!$E$2:$E$4687,місяць!$A$2:$A$4687,A4,місяць!$B$2:$B$4687,B4,місяць!$C$2:$C$4687,C4,місяць!$D$2:$D$4687,Лист1!$D$1) -> 243 | E4: =SUMIFS(місяць!$E$2:$E$4687,місяць!$A$2:$A$4687,A4,місяць!$B$2:$B$4687,B4,місяць!$C$2:$C$4687,C4,місяць!$D$2:$D$4687,Лист1!$E$1) -> 268 | F4: =SUMIFS(місяць!$E$2:$E$4687,місяць!$A$2:$A$4687,A4,місяць!$B$2:$B$4687,B4,місяць!$C$2:$C$4687,C4,місяць!$D$2:$D$4687,Лист1!$F$1) -> 334 | G4: =D4-E4 -> -25 | H4: =(D4/E4)-1 -> -0.093283582 | J4: =D4-F4 -> -91 | K4: =(D4/F4)-1 -> -0.27245509 | M4: Господарства населення | N4: =D4/D2*100% -> 0.4770318 | AA4: ="Січ.-"& CHOOSE(MOD(ROW()-ROW($A$1),12)+1, "січ.","лют.","бер.","кві.","тра.","чер.", "лип.","сер.","вер.","жов.","лис.","гру.") &" "&(2024+INT((ROW()-ROW($A$1))/12)) -> Січ.-кві. 2024 | AB4: =DATE(YEAR(AB3),MONTH(AB3)+1,1) -> 45383
AA5: ="Січ.-"& CHOOSE(MOD(ROW()-ROW($A$1),12)+1, "січ.","лют.","бер.","кві.","тра.","чер.", "лип.","сер.","вер.","жов.","лис.","гру.") &" "&(2024+INT((ROW()-ROW($A$1))/12)) -> Січ.-тра. 2024 | AB5: =DATE(YEAR(AB4),MONTH(AB4)+1,1) -> 45413
AA6: ="Січ.-"& CHOOSE(MOD(ROW()-ROW($A$1),12)+1, "січ.","лют.","бер.","кві.","тра.","чер.", "лип.","сер.","вер.","жов.","лис.","гру.") &" "&(2024+INT((ROW()-ROW($A$1))/12)) -> Січ.-чер. 2024 | AB6: =DATE(YEAR(AB5),MONTH(AB5)+1,1) -> 45444
AA7: ="Січ.-"& CHOOSE(MOD(ROW()-ROW($A$1),12)+1, "січ.","лют.","бер.","кві.","тра.","чер.", "лип.","сер.","вер.","жов.","лис.","гру.") &" "&(2024+INT((ROW()-ROW($A$1))/12)) -> Січ.-лип. 2024 | AB7: =DATE(YEAR(AB6),MONTH(AB6)+1,1) -> 45474
A8: Територіальний розріз | B8: Розріз | C8: Вид господарства | D8: =B$16 -> Січ.-вер. 2026 | E8: =B$17 -> Січ.-сер. 2026 | F8: =B$18 -> Січ.-вер. 2025 | G8: 26/25 | H8: 26/25 | M8: місяць | AA8: ="Січ.-"& CHOOSE(MOD(ROW()-ROW($A$1),12)+1, "січ.","лют.","бер.","кві.","тра.","чер.", "лип.","сер.","вер.","жов.","лис.","гру.") &" "&(2024+INT((ROW()-ROW($A$1))/12)) -> Січ.-сер. 2024 | AB8: =DATE(YEAR(AB7),MONTH(AB7)+1,1) -> 45505
A9: Україна | B9: Молоко | C9: Господарства усіх категорій | D9: =SUMIFS(період!$E$2:$E$4746,період!$A$2:$A$4746,A9,період!$B$2:$B$4746,B9,період!$C$2:$C$4746,Лист1!C9,період!$D$2:$D$4746,Лист1!$D$8) -> 4612 | E9: =SUMIFS(період!$E$2:$E$4746,період!$A$2:$A$4746,A9,період!$B$2:$B$4746,B9,період!$C$2:$C$4746,Лист1!C9,період!$D$2:$D$4746,Лист1!$E$8) -> 4102.6 | F9: =SUMIFS(період!$E$2:$E$4746,період!$A$2:$A$4746,A9,період!$B$2:$B$4746,B9,період!$C$2:$C$4746,Лист1!C9,період!$D$2:$D$4746,Лист1!$F$8) -> 5310.9 | G9: =D9-F9 -> -698.9 | H9: =(D9/F9)-1 -> -0.13159728 | M9: =D9-E9 -> 509.4 | AA9: ="Січ.-"& CHOOSE(MOD(ROW()-ROW($A$1),12)+1, "січ.","лют.","бер.","кві.","тра.","чер.", "лип.","сер.","вер.","жов.","лис.","гру.") &" "&(2024+INT((ROW()-ROW($A$1))/12)) -> Січ.-вер. 2024 | AB9: =DATE(YEAR(AB8),MONTH(AB8)+1,1) -> 45536
A10: Україна | B10: Молоко | C10: Підприємства | D10: =SUMIFS(період!$E$2:$E$4746,період!$A$2:$A$4746,A10,період!$B$2:$B$4746,B10,період!$C$2:$C$4746,Лист1!C10,період!$D$2:$D$4746,Лист1!$D$8) -> 2477.2 | E10: =SUMIFS(період!$E$2:$E$4746,період!$A$2:$A$4746,A10,період!$B$2:$B$4746,B10,період!$C$2:$C$4746,Лист1!C10,період!$D$2:$D$4746,Лист1!$E$8) -> 2210.8 | F10: =SUMIFS(період!$E$2:$E$4746,період!$A$2:$A$4746,A10,період!$B$2:$B$4746,B10,період!$C$2:$C$4746,Лист1!C10,період!$D$2:$D$4746,Лист1!$F$8) -> 2384.8 | G10: =D10-F10 -> 92.4 | H10: =(D10/F10)-1 -> 0.038745387 | J10: Підприємства | K10: =D10/D9*100% -> 0.53712056 | M10: =D10-E10 -> 266.4 | AA10: ="Січ.-"& CHOOSE(MOD(ROW()-ROW($A$1),12)+1, "січ.","лют.","бер.","кві.","тра.","чер.", "лип.","сер.","вер.","жов.","лис.","гру.") &" "&(2024+INT((ROW()-ROW($A$1))/12)) -> Січ.-жов. 2024 | AB10: =DATE(YEAR(AB9),MONTH(AB9)+1,1) -> 45566
A11: Україна | B11: Молоко | C11: Господарства населення | D11: =SUMIFS(період!$E$2:$E$4746,період!$A$2:$A$4746,A11,період!$B$2:$B$4746,B11,період!$C$2:$C$4746,Лист1!C11,період!$D$2:$D$4746,Лист1!$D$8) -> 2134.8 | E11: =SUMIFS(період!$E$2:$E$4746,період!$A$2:$A$4746,A11,період!$B$2:$B$4746,B11,період!$C$2:$C$4746,Лист1!C11,період!$D$2:$D$4746,Лист1!$E$8) -> 1891.8 | F11: =SUMIFS(період!$E$2:$E$4746,період!$A$2:$A$4746,A11,період!$B$2:$B$4746,B11,період!$C$2:$C$4746,Лист1!C11,період!$D$2:$D$4746,Лист1!$F$8) -> 2926.1 | G11: =D11-F11 -> -791.3 | H11: =(D11/F11)-1 -> -0.27042822 | J11: Господарства населення | K11: =D11/D9*100% -> 0.46287944 | M11: =D11-E11 -> 243 | AA11: ="Січ.-"& CHOOSE(MOD(ROW()-ROW($A$1),12)+1, "січ.","лют.","бер.","кві.","тра.","чер.", "лип.","сер.","вер.","жов.","лис.","гру.") &" "&(2024+INT((ROW()-ROW($A$1))/12)) -> Січ.-лис. 2024 | AB11: =DATE(YEAR(AB10),MONTH(AB10)+1,1) -> 45597
AA12: ="Січ.-"& CHOOSE(MOD(ROW()-ROW($A$1),12)+1, "січ.","лют.","бер.","кві.","тра.","чер.", "лип.","сер.","вер.","жов.","лис.","гру.") &" "&(2024+INT((ROW()-ROW($A$1))/12)) -> Січ.-гру. 2024 | AB12: =DATE(YEAR(AB11),MONTH(AB11)+1,1) -> 45627
AA13: ="Січ.-"& CHOOSE(MOD(ROW()-ROW($A$1),12)+1, "січ.","лют.","бер.","кві.","тра.","чер.", "лип.","сер.","вер.","жов.","лис.","гру.") &" "&(2024+INT((ROW()-ROW($A$1))/12)) -> Січ.-січ. 2025 | AB13: =DATE(YEAR(AB12),MONTH(AB12)+1,1) -> 45658
A14: Період | D14: Місяць | AA14: ="Січ.-"& CHOOSE(MOD(ROW()-ROW($A$1),12)+1, "січ.","лют.","бер.","кві.","тра.","чер.", "лип.","сер.","вер.","жов.","лис.","гру.") &" "&(2024+INT((ROW()-ROW($A$1))/12)) -> Січ.-лют. 2025 | AB14: =DATE(YEAR(AB13),MONTH(AB13)+1,1) -> 45689
AA15: ="Січ.-"& CHOOSE(MOD(ROW()-ROW($A$1),12)+1, "січ.","лют.","бер.","кві.","тра.","чер.", "лип.","сер.","вер.","жов.","лис.","гру.") &" "&(2024+INT((ROW()-ROW($A$1))/12)) -> Січ.-бер. 2025 | AB15: =DATE(YEAR(AB14),MONTH(AB14)+1,1) -> 45717
A16: Поточна | B16: Січ.-вер. 2026 | D16: Поточна | E16: 46266 | AA16: ="Січ.-"& CHOOSE(MOD(ROW()-ROW($A$1),12)+1, "січ.","лют.","бер.","кві.","тра.","чер.", "лип.","сер.","вер.","жов.","лис.","гру.") &" "&(2024+INT((ROW()-ROW($A$1))/12)) -> Січ.-кві. 2025 | AB16: =DATE(YEAR(AB15),MONTH(AB15)+1,1) -> 45748
A17: Попередня | B17: Січ.-сер. 2026 | D17: Попередня | E17: 46235 | AA17: ="Січ.-"& CHOOSE(MOD(ROW()-ROW($A$1),12)+1, "січ.","лют.","бер.","кві.","тра.","чер.", "лип.","сер.","вер.","жов.","лис.","гру.") &" "&(2024+INT((ROW()-ROW($A$1))/12)) -> Січ.-тра. 2025 | AB17: =DATE(YEAR(AB16),MONTH(AB16)+1,1) -> 45778
A18: Минулорічна | B18: Січ.-вер. 2025 | D18: Минулорічна | E18: 45901 | AA18: ="Січ.-"& CHOOSE(MOD(ROW()-ROW($A$1),12)+1, "січ.","лют.","бер.","кві.","тра.","чер.", "лип.","сер.","вер.","жов.","лис.","гру.") &" "&(2024+INT((ROW()-ROW($A$1))/12)) -> Січ.-чер. 2025 | AB18: =DATE(YEAR(AB17),MONTH(AB17)+1,1) -> 45809
AA19: ="Січ.-"& CHOOSE(MOD(ROW()-ROW($A$1),12)+1, "січ.","лют.","бер.","кві.","тра.","чер.", "лип.","сер.","вер.","жов.","лис.","гру.") &" "&(2024+INT((ROW()-ROW($A$1))/12)) -> Січ.-лип. 2025 | AB19: =DATE(YEAR(AB18),MONTH(AB18)+1,1) -> 45839
AA20: ="Січ.-"& CHOOSE(MOD(ROW()-ROW($A$1),12)+1, "січ.","лют.","бер.","кві.","тра.","чер.", "лип.","сер.","вер.","жов.","лис.","гру.") &" "&(2024+INT((ROW()-ROW($A$1))/12)) -> Січ.-сер. 2025 | AB20: =DATE(YEAR(AB19),MONTH(AB19)+1,1) -> 45870
AA21: ="Січ.-"& CHOOSE(MOD(ROW()-ROW($A$1),12)+1, "січ.","лют.","бер.","кві.","тра.","чер.", "лип.","сер.","вер.","жов.","лис.","гру.") &" "&(2024+INT((ROW()-ROW($A$1))/12)) -> Січ.-вер. 2025 | AB21: =DATE(YEAR(AB20),MONTH(AB20)+1,1) -> 45901
AA22: ="Січ.-"& CHOOSE(MOD(ROW()-ROW($A$1),12)+1, "січ.","лют.","бер.","кві.","тра.","чер.", "лип.","сер.","вер.","жов.","лис.","гру.") &" "&(2024+INT((ROW()-ROW($A$1))/12)) -> Січ.-жов. 2025 | AB22: =DATE(YEAR(AB21),MONTH(AB21)+1,1) -> 45931
AA23: ="Січ.-"& CHOOSE(MOD(ROW()-ROW($A$1),12)+1, "січ.","лют.","бер.","кві.","тра.","чер.", "лип.","сер.","вер.","жов.","лис.","гру.") &" "&(2024+INT((ROW()-ROW($A$1))/12)) -> Січ.-лис. 2025 | AB23: =DATE(YEAR(AB22),MONTH(AB22)+1,1) -> 45962
AA24: ="Січ.-"& CHOOSE(MOD(ROW()-ROW($A$1),12)+1, "січ.","лют.","бер.","кві.","тра.","чер.", "лип.","сер.","вер.","жов.","лис.","гру.") &" "&(2024+INT((ROW()-ROW($A$1))/12)) -> Січ.-гру. 2025 | AB24: =DATE(YEAR(AB23),MONTH(AB23)+1,1) -> 45992
AA25: ="Січ.-"& CHOOSE(MOD(ROW()-ROW($A$1),12)+1, "січ.","лют.","бер.","кві.","тра.","чер.", "лип.","сер.","вер.","жов.","лис.","гру.") &" "&(2024+INT((ROW()-ROW($A$1))/12)) -> Січ.-січ. 2026 | AB25: =DATE(YEAR(AB24),MONTH(AB24)+1,1) -> 46023
AA26: ="Січ.-"& CHOOSE(MOD(ROW()-ROW($A$1),12)+1, "січ.","лют.","бер.","кві.","тра.","чер.", "лип.","сер.","вер.","жов.","лис.","гру.") &" "&(2024+INT((ROW()-ROW($A$1))/12)) -> Січ.-лют. 2026 | AB26: =DATE(YEAR(AB25),MONTH(AB25)+1,1) -> 46054
AA27: ="Січ.-"& CHOOSE(MOD(ROW()-ROW($A$1),12)+1, "січ.","лют.","бер.","кві.","тра.","чер.", "лип.","сер.","вер.","жов.","лис.","гру.") &" "&(2024+INT((ROW()-ROW($A$1))/12)) -> Січ.-бер. 2026 | AB27: =DATE(YEAR(AB26),MONTH(AB26)+1,1) -> 46082
AA28: ="Січ.-"& CHOOSE(MOD(ROW()-ROW($A$1),12)+1, "січ.","лют.","бер.","кві.","тра.","чер.", "лип.","сер.","вер.","жов.","лис.","гру.") &" "&(2024+INT((ROW()-ROW($A$1))/12)) -> Січ.-кві. 2026 | AB28: =DATE(YEAR(AB27),MONTH(AB27)+1,1) -> 46113
AA29: ="Січ.-"& CHOOSE(MOD(ROW()-ROW($A$1),12)+1, "січ.","лют.","бер.","кві.","тра.","чер.", "лип.","сер.","вер.","жов.","лис.","гру.") &" "&(2024+INT((ROW()-ROW($A$1))/12)) -> Січ.-тра. 2026 | AB29: =DATE(YEAR(AB28),MONTH(AB28)+1,1) -> 46143
AA30: ="Січ.-"& CHOOSE(MOD(ROW()-ROW($A$1),12)+1, "січ.","лют.","бер.","кві.","тра.","чер.", "лип.","сер.","вер.","жов.","лис.","гру.") &" "&(2024+INT((ROW()-ROW($A$1))/12)) -> Січ.-чер. 2026 | AB30: =DATE(YEAR(AB29),MONTH(AB29)+1,1) -> 46174
... AA36: ="Січ.-"& CHOOSE(MOD(ROW()-ROW($A$1),12)+1, "січ.","лют.","бер.","кві.","тра.","чер.", "лип.","сер.","вер.","жов.","лис.","гру.") &" "&(2024+INT((ROW()-ROW($A$1))/12)) -> Січ.-гру. 2026 | AB36: =DATE(YEAR(AB35),MONTH(AB35)+1,1) -> 46357

Sheet усі
A1: Територіальний розріз | B1: Розріз | C1: Вид господарства | D1: =Лист1!B$16 -> Січ.-вер. 2026 | E1: =Лист1!B$18 -> Січ.-вер. 2025 | F1: =Лист1!J$1 -> 26/25 | H1: Ріст по областям | J1: =COUNTIF(F2:F25,">0") -> 3
A2: Вінницька | B2: Молоко | C2: Господарства усіх категорій | D2: =SUMIFS(період!$E$2:$E$4746,період!$A$2:$A$4746,A2,період!$B$2:$B$4746,B2,період!$C$2:$C$4746,C2,період!$D$2:$D$4746,$D$1) -> 414.4 | E2: =SUMIFS(період!$E$2:$E$4746,період!$A$2:$A$4746,A2,період!$B$2:$B$4746,B2,період!$C$2:$C$4746,C2,період!$D$2:$D$4746,$E$1) -> 431.6 | F2: =(D2/E2)-1 -> -0.039851715 | H2: =IF(F2>0,A2,"") | I2: =IF(F2>0,F2,"")
A3: Волинська | B3: Молоко | C3: Господарства усіх категорій | D3: =SUMIFS(період!$E$2:$E$4746,період!$A$2:$A$4746,A3,період!$B$2:$B$4746,B3,період!$C$2:$C$4746,C3,період!$D$2:$D$4746,$D$1) -> 189.1 | E3: =SUMIFS(період!$E$2:$E$4746,період!$A$2:$A$4746,A3,період!$B$2:$B$4746,B3,період!$C$2:$C$4746,C3,період!$D$2:$D$4746,$E$1) -> 214 | F3: =(D3/E3)-1 -> -0.11635514 | H3: =IF(F3>0,A3,"") | I3: =IF(F3>0,F3,"")
A4: Дніпропетровська | B4: Молоко | C4: Господарства усіх категорій | D4: =SUMIFS(період!$E$2:$E$4746,період!$A$2:$A$4746,A4,період!$B$2:$B$4746,B4,період!$C$2:$C$4746,C4,період!$D$2:$D$4746,$D$1) -> 125.8 | E4: =SUMIFS(період!$E$2:$E$4746,період!$A$2:$A$4746,A4,період!$B$2:$B$4746,B4,період!$C$2:$C$4746,C4,період!$D$2:$D$4746,$E$1) -> 148.9 | F4: =(D4/E4)-1 -> -0.15513768 | H4: =IF(F4>0,A4,"") | I4: =IF(F4>0,F4,"")
A5: Донецька | B5: Молоко | C5: Господарства усіх категорій | D5: =SUMIFS(період!$E$2:$E$4746,період!$A$2:$A$4746,A5,період!$B$2:$B$4746,B5,період!$C$2:$C$4746,C5,період!$D$2:$D$4746,$D$1) -> 4.5 | E5: =SUMIFS(період!$E$2:$E$4746,період!$A$2:$A$4746,A5,період!$B$2:$B$4746,B5,період!$C$2:$C$4746,C5,період!$D$2:$D$4746,$E$1) -> 13.4 | F5: =(D5/E5)-1 -> -0.6641791 | H5: =IF(F5>0,A5,"") | I5: =IF(F5>0,F5,"")
A6: Житомирська | B6: Молоко | C6: Господарства усіх категорій | D6: =SUMIFS(період!$E$2:$E$4746,період!$A$2:$A$4746,A6,період!$B$2:$B$4746,B6,період!$C$2:$C$4746,C6,період!$D$2:$D$4746,$D$1) -> 248.5 | E6: =SUMIFS(період!$E$2:$E$4746,період!$A$2:$A$4746,A6,період!$B$2:$B$4746,B6,період!$C$2:$C$4746,C6,період!$D$2:$D$4746,$E$1) -> 305.5 | F6: =(D6/E6)-1 -> -0.18657938 | H6: =IF(F6>0,A6,"") | I6: =IF(F6>0,F6,"")
A7: Закарпатська | B7: Молоко | C7: Господарства усіх категорій | D7: =SUMIFS(період!$E$2:$E$4746,період!$A$2:$A$4746,A7,період!$B$2:$B$4746,B7,період!$C$2:$C$4746,C7,період!$D$2:$D$4746,$D$1) -> 59.2 | E7: =SUMIFS(період!$E$2:$E$4746,період!$A$2:$A$4746,A7,період!$B$2:$B$4746,B7,період!$C$2:$C$4746,C7,період!$D$2:$D$4746,$E$1) -> 161.2 | F7: =(D7/E7)-1 -> -0.63275434 | H7: =IF(F7>0,A7,"") | I7: =IF(F7>0,F7,"")
A8: Запорізька | B8: Молоко | C8: Господарства усіх категорій | D8: =SUMIFS(період!$E$2:$E$4746,період!$A$2:$A$4746,A8,період!$B$2:$B$4746,B8,період!$C$2:$C$4746,C8,період!$D$2:$D$4746,$D$1) -> 8.6 | E8: =SUMIFS(період!$E$2:$E$4746,період!$A$2:$A$4746,A8,період!$B$2:$B$4746,B8,період!$C$2:$C$4746,C8,період!$D$2:$D$4746,$E$1) -> 13.4 | F8: =(D8/E8)-1 -> -0.35820896 | H8: =IF(F8>0,A8,"") | I8: =IF(F8>0,F8,"")
A9: Івано-Франківська | B9: Молоко | C9: Господарства усіх категорій | D9: =SUMIFS(період!$E$2:$E$4746,період!$A$2:$A$4746,A9,період!$B$2:$B$4746,B9,період!$C$2:$C$4746,C9,період!$D$2:$D$4746,$D$1) -> 142.5 | E9: =SUMIFS(період!$E$2:$E$4746,період!$A$2:$A$4746,A9,період!$B$2:$B$4746,B9,період!$C$2:$C$4746,C9,період!$D$2:$D$4746,$E$1) -> 180.2 | F9: =(D9/E9)-1 -> -0.20921199 | H9: =IF(F9>0,A9,"") | I9: =IF(F9>0,F9,"")
A10: Київська | B10: Молоко | C10: Господарства усіх категорій | D10: =SUMIFS(період!$E$2:$E$4746,період!$A$2:$A$4746,A10,період!$B$2:$B$4746,B10,період!$C$2:$C$4746,C10,період!$D$2:$D$4746,$D$1) -> 255.7 | E10: =SUMIFS(період!$E$2:$E$4746,період!$A$2:$A$4746,A10,період!$B$2:$B$4746,B10,період!$C$2:$C$4746,C10,період!$D$2:$D$4746,$E$1) -> 253 | F10: =(D10/E10)-1 -> 0.010671937 | H10: =IF(F10>0,A10,"") -> Київська | I10: =IF(F10>0,F10,"") -> 0.010671937
A11: Кіровоградська | B11: Молоко | C11: Господарства усіх категорій | D11: =SUMIFS(період!$E$2:$E$4746,період!$A$2:$A$4746,A11,період!$B$2:$B$4746,B11,період!$C$2:$C$4746,C11,період!$D$2:$D$4746,$D$1) -> 176 | E11: =SUMIFS(період!$E$2:$E$4746,період!$A$2:$A$4746,A11,період!$B$2:$B$4746,B11,період!$C$2:$C$4746,C11,період!$D$2:$D$4746,$E$1) -> 193.4 | F11: =(D11/E11)-1 -> -0.089968976 | H11: =IF(F11>0,A11,"") | I11: =IF(F11>0,F11,"")
A12: Луганська | B12: Молоко | C12: Господарства усіх категорій | D12: =SUMIFS(період!$E$2:$E$4746,період!$A$2:$A$4746,A12,період!$B$2:$B$4746,B12,період!$C$2:$C$4746,C12,період!$D$2:$D$4746,$D$1) -> 0 | E12: =SUMIFS(період!$E$2:$E$4746,період!$A$2:$A$4746,A12,період!$B$2:$B$4746,B12,період!$C$2:$C$4746,C12,період!$D$2:$D$4746,$E$1) -> 35.1 | F12: 0 | H12: =IF(F12>0,A12,"") | I12: =IF(F12>0,F12,"")
A13: Львівська | B13: Молоко | C13: Господарства усіх категорій | D13: =SUMIFS(період!$E$2:$E$4746,період!$A$2:$A$4746,A13,період!$B$2:$B$4746,B13,період!$C$2:$C$4746,C13,період!$D$2:$D$4746,$D$1) -> 160 | E13: =SUMIFS(період!$E$2:$E$4746,період!$A$2:$A$4746,A13,період!$B$2:$B$4746,B13,період!$C$2:$C$4746,C13,період!$D$2:$D$4746,$E$1) -> 217.8 | F13: =(D13/E13)-1 -> -0.26538108 | H13: =IF(F13>0,A13,"") | I13: =IF(F13>0,F13,"")
A14: Миколаївська | B14: Молоко | C14: Господарства усіх категорій | D14: =SUMIFS(період!$E$2:$E$4746,період!$A$2:$A$4746,A14,період!$B$2:$B$4746,B14,період!$C$2:$C$4746,C14,період!$D$2:$D$4746,$D$1) -> 140.8 | E14: =SUMIFS(період!$E$2:$E$4746,період!$A$2:$A$4746,A14,період!$B$2:$B$4746,B14,період!$C$2:$C$4746,C14,період!$D$2:$D$4746,$E$1) -> 150.9 | F14: =(D14/E14)-1 -> -0.066931743 | H14: =IF(F14>0,A14,"") | I14: =IF(F14>0,F14,"")
A15: Одеська | B15: Молоко | C15: Господарства усіх категорій | D15: =SUMIFS(період!$E$2:$E$4746,період!$A$2:$A$4746,A15,період!$B$2:$B$4746,B15,період!$C$2:$C$4746,C15,період!$D$2:$D$4746,$D$1) -> 207.6 | E15: =SUMIFS(період!$E$2:$E$4746,період!$A$2:$A$4746,A15,період!$B$2:$B$4746,B15,період!$C$2:$C$4746,C15,період!$D$2:$D$4746,$E$1) -> 216.7 | F15: =(D15/E15)-1 -> -0.041993539 | H15: =IF(F15>0,A15,"") | I15: =IF(F15>0,F15,"")
A16: Полтавська | B16: Молоко | C16: Господарства усіх категорій | D16: =SUMIFS(період!$E$2:$E$4746,період!$A$2:$A$4746,A16,період!$B$2:$B$4746,B16,період!$C$2:$C$4746,C16,період!$D$2:$D$4746,$D$1) -> 476.7 | E16: =SUMIFS(період!$E$2:$E$4746,період!$A$2:$A$4746,A16,період!$B$2:$B$4746,B16,період!$C$2:$C$4746,C16,період!$D$2:$D$4746,$E$1) -> 508.6 | F16: =(D16/E16)-1 -> -0.062721195 | H16: =IF(F16>0,A16,"") | I16: =IF(F16>0,F16,"")
A17: Рівненська | B17: Молоко | C17: Господарства усіх категорій | D17: =SUMIFS(період!$E$2:$E$4746,період!$A$2:$A$4746,A17,період!$B$2:$B$4746,B17,період!$C$2:$C$4746,C17,період!$D$2:$D$4746,$D$1) -> 173.3 | E17: =SUMIFS(період!$E$2:$E$4746,період!$A$2:$A$4746,A17,період!$B$2:$B$4746,B17,період!$C$2:$C$4746,C17,період!$D$2:$D$4746,$E$1) -> 195.5 | F17: =(D17/E17)-1 -> -0.11355499 | H17: =IF(F17>0,A17,"") | I17: =IF(F17>0,F17,"")
A18: Сумська | B18: Молоко | C18: Господарства усіх категорій | D18: =SUMIFS(період!$E$2:$E$4746,період!$A$2:$A$4746,A18,період!$B$2:$B$4746,B18,період!$C$2:$C$4746,C18,період!$D$2:$D$4746,$D$1) -> 149.4 | E18: =SUMIFS(період!$E$2:$E$4746,період!$A$2:$A$4746,A18,період!$B$2:$B$4746,B18,період!$C$2:$C$4746,C18,період!$D$2:$D$4746,$E$1) -> 181 | F18: =(D18/E18)-1 -> -0.17458564 | H18: =IF(F18>0,A18,"") | I18: =IF(F18>0,F18,"")
A19: Тернопільська | B19: Молоко | C19: Господарства усіх категорій | D19: =SUMIFS(період!$E$2:$E$4746,період!$A$2:$A$4746,A19,період!$B$2:$B$4746,B19,період!$C$2:$C$4746,C19,період!$D$2:$D$4746,$D$1) -> 291.3 | E19: =SUMIFS(період!$E$2:$E$4746,період!$A$2:$A$4746,A19,період!$B$2:$B$4746,B19,період!$C$2:$C$4746,C19,період!$D$2:$D$4746,$E$1) -> 382 | F19: =(D19/E19)-1 -> -0.23743455 | H19: =IF(F19>0,A19,"") | I19: =IF(F19>0,F19,"")
A20: Харківська | B20: Молоко | C20: Господарства усіх категорій | D20: =SUMIFS(період!$E$2:$E$4746,період!$A$2:$A$4746,A20,період!$B$2:$B$4746,B20,період!$C$2:$C$4746,C20,період!$D$2:$D$4746,$D$1) -> 168.4 | E20: =SUMIFS(період!$E$2:$E$4746,період!$A$2:$A$4746,A20,період!$B$2:$B$4746,B20,період!$C$2:$C$4746,C20,період!$D$2:$D$4746,$E$1) -> 173.6 | F20: =(D20/E20)-1 -> -0.029953917 | H20: =IF(F20>0,A20,"") | I20: =IF(F20>0,F20,"")
A21: Херсонська | B21: Молоко | C21: Господарства усіх категорій | D21: =SUMIFS(період!$E$2:$E$4746,період!$A$2:$A$4746,A21,період!$B$2:$B$4746,B21,період!$C$2:$C$4746,C21,період!$D$2:$D$4746,$D$1) -> 31.8 | E21: =SUMIFS(період!$E$2:$E$4746,період!$A$2:$A$4746,A21,період!$B$2:$B$4746,B21,період!$C$2:$C$4746,C21,період!$D$2:$D$4746,$E$1) -> 46 | F21: 0 | H21: =IF(F21>0,A21,"") | I21: =IF(F21>0,F21,"")
A22: Хмельницька | B22: Молоко | C22: Господарства усіх категорій | D22: =SUMIFS(період!$E$2:$E$4746,період!$A$2:$A$4746,A22,період!$B$2:$B$4746,B22,період!$C$2:$C$4746,C22,період!$D$2:$D$4746,$D$1) -> 433 | E22: =SUMIFS(період!$E$2:$E$4746,період!$A$2:$A$4746,A22,період!$B$2:$B$4746,B22,період!$C$2:$C$4746,C22,період!$D$2:$D$4746,$E$1) -> 511.2 | F22: =(D22/E22)-1 -> -0.1529734 | H22: =IF(F22>0,A22,"") | I22: =IF(F22>0,F22,"")
A23: Черкаська | B23: Молоко | C23: Господарства усіх категорій | D23: =SUMIFS(період!$E$2:$E$4746,період!$A$2:$A$4746,A23,період!$B$2:$B$4746,B23,період!$C$2:$C$4746,C23,період!$D$2:$D$4746,$D$1) -> 348.8 | E23: =SUMIFS(період!$E$2:$E$4746,період!$A$2:$A$4746,A23,період!$B$2:$B$4746,B23,період!$C$2:$C$4746,C23,період!$D$2:$D$4746,$E$1) -> 348.5 | F23: =(D23/E23)-1 -> 0.00086083214 | H23: =IF(F23>0,A23,"") -> Черкаська | I23: =IF(F23>0,F23,"") -> 0.00086083214
A24: Чернівецька | B24: Молоко | C24: Господарства усіх категорій | D24: =SUMIFS(період!$E$2:$E$4746,період!$A$2:$A$4746,A24,період!$B$2:$B$4746,B24,період!$C$2:$C$4746,C24,період!$D$2:$D$4746,$D$1) -> 78.7 | E24: =SUMIFS(період!$E$2:$E$4746,період!$A$2:$A$4746,A24,період!$B$2:$B$4746,B24,період!$C$2:$C$4746,C24,період!$D$2:$D$4746,$E$1) -> 116.3 | F24: =(D24/E24)-1 -> -0.32330181 | H24: =IF(F24>0,A24,"") | I24: =IF(F24>0,F24,"")
A25: Чернігівська | B25: Молоко | C25: Господарства усіх категорій | D25: =SUMIFS(період!$E$2:$E$4746,період!$A$2:$A$4746,A25,період!$B$2:$B$4746,B25,період!$C$2:$C$4746,C25,період!$D$2:$D$4746,$D$1) -> 327.9 | E25: =SUMIFS(період!$E$2:$E$4746,період!$A$2:$A$4746,A25,період!$B$2:$B$4746,B25,період!$C$2:$C$4746,C25,період!$D$2:$D$4746,$E$1) -> 313.1 | F25: =(D25/E25)-1 -> 0.047269243 | H25: =IF(F25>0,A25,"") -> Чернігівська | I25: =IF(F25>0,F25,"") -> 0.047269243

Sheet мтф
A1: Територіальний розріз | B1: Розріз | C1: Вид господарства | D1: =Лист1!B$16 -> Січ.-вер. 2026 | E1: =Лист1!B$18 -> Січ.-вер. 2025 | F1: =Лист1!J$1 -> 26/25 | H1: Ріст по областям | J1: =COUNTIF(F2:F25,">0,001") -> 13 | N1: сііч. 26
A2: Вінницька | B2: Молоко | C2: Підприємства | D2: =SUMIFS(період!$E$2:$E$4746,період!$A$2:$A$4746,A2,період!$B$2:$B$4746,B2,період!$C$2:$C$4746,C2,період!$D$2:$D$4746,$D$1) -> 223.1 | E2: =SUMIFS(період!$E$2:$E$4746,період!$A$2:$A$4746,A2,період!$B$2:$B$4746,B2,період!$C$2:$C$4746,C2,період!$D$2:$D$4746,$E$1) -> 212.7 | F2: =IFERROR(D2/E2-"1","") -> 0.048895157 | H2: =IF(F2>0.001,A2,"") -> Вінницька | I2: =IF(F2>0.001,F2,"") -> 0.048895157 | L2: 48.5 | M2: 24.6 | N2: 23.9 | O2: 21 | Q2: 44.9 | R2: 23.9
A3: Волинська | B3: Молоко | C3: Підприємства | D3: =SUMIFS(період!$E$2:$E$4746,період!$A$2:$A$4746,A3,період!$B$2:$B$4746,B3,період!$C$2:$C$4746,C3,період!$D$2:$D$4746,$D$1) -> 94.7 | E3: =SUMIFS(період!$E$2:$E$4746,період!$A$2:$A$4746,A3,період!$B$2:$B$4746,B3,період!$C$2:$C$4746,C3,період!$D$2:$D$4746,$E$1) -> 91.1 | F3: =IFERROR(D3/E3-"1","") -> 0.039517014 | H3: =IF(F3>0.001,A3,"") -> Волинська | I3: =IF(F3>0.001,F3,"") -> 0.039517014 | L3: 20.3 | M3: 10.6 | N3: 9.7 | O3: 9 | Q3: 18.7 | R3: 9.7
A4: Дніпропетровська | B4: Молоко | C4: Підприємства | D4: =SUMIFS(період!$E$2:$E$4746,період!$A$2:$A$4746,A4,період!$B$2:$B$4746,B4,період!$C$2:$C$4746,C4,період!$D$2:$D$4746,$D$1) -> 40.7 | E4: =SUMIFS(період!$E$2:$E$4746,період!$A$2:$A$4746,A4,період!$B$2:$B$4746,B4,період!$C$2:$C$4746,C4,період!$D$2:$D$4746,$E$1) -> 47.2 | F4: =IFERROR(D4/E4-"1","") -> -0.13771186 | H4: =IF(F4>0.001,A4,"") | I4: =IF(F4>0.001,F4,"") | L4: 9 | M4: 4.8 | N4: 4.2 | O4: 4.9 | Q4: 10.3 | R4: 5.4
A5: Донецька | B5: Молоко | C5: Підприємства | D5: =SUMIFS(період!$E$2:$E$4746,період!$A$2:$A$4746,A5,період!$B$2:$B$4746,B5,період!$C$2:$C$4746,C5,період!$D$2:$D$4746,$D$1) -> 0 | E5: =SUMIFS(період!$E$2:$E$4746,період!$A$2:$A$4746,A5,період!$B$2:$B$4746,B5,період!$C$2:$C$4746,C5,період!$D$2:$D$4746,$E$1) -> 0 | F5: =IFERROR(D5/E5-"1","") | H5: =IF(F5>0.001,A5,"") -> Донецька | I5: =IF(F5>0.001,F5,"") | L5: 0 | M5: 0 | N5: 0 | O5: 0 | Q5: 0 | R5: 0
A6: Житомирська | B6: Молоко | C6: Підприємства | D6: =SUMIFS(період!$E$2:$E$4746,період!$A$2:$A$4746,A6,період!$B$2:$B$4746,B6,період!$C$2:$C$4746,C6,період!$D$2:$D$4746,$D$1) -> 129.2 | E6: =SUMIFS(період!$E$2:$E$4746,період!$A$2:$A$4746,A6,період!$B$2:$B$4746,B6,період!$C$2:$C$4746,C6,період!$D$2:$D$4746,$E$1) -> 112.3 | F6: =IFERROR(D6/E6-"1","") -> 0.15048976 | H6: =IF(F6>0.001,A6,"") -> Житомирська | I6: =IF(F6>0.001,F6,"") -> 0.15048976 | L6: 24.8 | M6: 12.9 | N6: 11.9 | O6: 11.1 | Q6: 23.1 | R6: 12
A7: Закарпатська | B7: Молоко | C7: Підприємства | D7: =SUMIFS(період!$E$2:$E$4746,період!$A$2:$A$4746,A7,період!$B$2:$B$4746,B7,період!$C$2:$C$4746,C7,період!$D$2:$D$4746,$D$1) -> 0.9 | E7: =SUMIFS(період!$E$2:$E$4746,період!$A$2:$A$4746,A7,період!$B$2:$B$4746,B7,період!$C$2:$C$4746,C7,період!$D$2:$D$4746,$E$1) -> 1 | F7: =IFERROR(D7/E7-"1","") -> -0.1 | H7: =IF(F7>0.001,A7,"") | I7: =IF(F7>0.001,F7,"") | L7: 0.1 | M7: 0.1 | N7: 0 | O7: 0 | Q7: 0.1 | R7: 0.1
A8: Запорізька | B8: Молоко | C8: Підприємства | D8: =SUMIFS(період!$E$2:$E$4746,період!$A$2:$A$4746,A8,період!$B$2:$B$4746,B8,період!$C$2:$C$4746,C8,період!$D$2:$D$4746,$D$1) -> 1.7 | E8: =SUMIFS(період!$E$2:$E$4746,період!$A$2:$A$4746,A8,період!$B$2:$B$4746,B8,період!$C$2:$C$4746,C8,період!$D$2:$D$4746,$E$1) -> 2.9 | F8: =IFERROR(D8/E8-"1","") -> -0.4137931 | H8: =IF(F8>0.001,A8,"") | I8: =IF(F8>0.001,F8,"") | L8: 0.4 | M8: 0.2 | N8: 0.2 | O8: 0.3 | Q8: 0.6 | R8: 0.3
A9: Івано-Франківська | B9: Молоко | C9: Підприємства | D9: =SUMIFS(період!$E$2:$E$4746,період!$A$2:$A$4746,A9,період!$B$2:$B$4746,B9,період!$C$2:$C$4746,C9,період!$D$2:$D$4746,$D$1) -> 14.6 | E9: =SUMIFS(період!$E$2:$E$4746,період!$A$2:$A$4746,A9,період!$B$2:$B$4746,B9,період!$C$2:$C$4746,C9,період!$D$2:$D$4746,$E$1) -> 12.6 | F9: =IFERROR(D9/E9-"1","") -> 0.15873016 | H9: =IF(F9>0.001,A9,"") -> Івано-Франківська | I9: =IF(F9>0.001,F9,"") -> 0.15873016 | L9: 3.1 | M9: 1.6 | N9: 1.5 | O9: 1.3 | Q9: 2.7 | R9: 1.4
A10: Київська | B10: Молоко | C10: Підприємства | D10: =SUMIFS(період!$E$2:$E$4746,період!$A$2:$A$4746,A10,період!$B$2:$B$4746,B10,період!$C$2:$C$4746,C10,період!$D$2:$D$4746,$D$1) -> 215 | E10: =SUMIFS(період!$E$2:$E$4746,період!$A$2:$A$4746,A10,період!$B$2:$B$4746,B10,період!$C$2:$C$4746,C10,період!$D$2:$D$4746,$E$1) -> 209.5 | F10: =IFERROR(D10/E10-"1","") -> 0.026252983 | H10: =IF(F10>0.001,A10,"") -> Київська | I10: =IF(F10>0.001,F10,"") -> 0.026252983 | L10: 44.8 | M10: 22.8 | N10: 22 | O10: 21.3 | Q10: 43.1 | R10: 21.8
A11: Кіровоградська | B11: Молоко | C11: Підприємства | D11: =SUMIFS(період!$E$2:$E$4746,період!$A$2:$A$4746,A11,період!$B$2:$B$4746,B11,період!$C$2:$C$4746,C11,період!$D$2:$D$4746,$D$1) -> 60.6 | E11: =SUMIFS(період!$E$2:$E$4746,період!$A$2:$A$4746,A11,період!$B$2:$B$4746,B11,період!$C$2:$C$4746,C11,період!$D$2:$D$4746,$E$1) -> 59.5 | F11: =IFERROR(D11/E11-"1","") -> 0.018487395 | H11: =IF(F11>0.001,A11,"") -> Кіровоградська | I11: =IF(F11>0.001,F11,"") -> 0.018487395 | L11: 12.1 | M11: 6.4 | N11: 5.7 | O11: 6 | Q11: 12.6 | R11: 6.6
A12: Луганська | B12: Молоко | C12: Підприємства | D12: =SUMIFS(період!$E$2:$E$4746,період!$A$2:$A$4746,A12,період!$B$2:$B$4746,B12,період!$C$2:$C$4746,C12,період!$D$2:$D$4746,$D$1) -> 0 | E12: =SUMIFS(період!$E$2:$E$4746,період!$A$2:$A$4746,A12,період!$B$2:$B$4746,B12,період!$C$2:$C$4746,C12,період!$D$2:$D$4746,$E$1) -> 0 | F12: =IFERROR(D12/E12-"1","") | H12: =IF(F12>0.001,A12,"") -> Луганська | I12: =IF(F12>0.001,F12,"") | L12: 0 | M12: 0 | N12: 0 | O12: 0 | Q12: 0 | R12: 0
A13: Львівська | B13: Молоко | C13: Підприємства | D13: =SUMIFS(період!$E$2:$E$4746,період!$A$2:$A$4746,A13,період!$B$2:$B$4746,B13,період!$C$2:$C$4746,C13,період!$D$2:$D$4746,$D$1) -> 29.3 | E13: =SUMIFS(період!$E$2:$E$4746,період!$A$2:$A$4746,A13,період!$B$2:$B$4746,B13,період!$C$2:$C$4746,C13,період!$D$2:$D$4746,$E$1) -> 25.5 | F13: =IFERROR(D13/E13-"1","") -> 0.14901961 | H13: =IF(F13>0.001,A13,"") -> Львівська | I13: =IF(F13>0.001,F13,"") -> 0.14901961 | L13: 5.9 | M13: 3.1 | N13: 2.8 | O13: 2.4 | Q13: 5.1 | R13: 2.7
... A25: Чернігівська | B25: Молоко | C25: Підприємства | D25: =SUMIFS(період!$E$2:$E$4746,період!$A$2:$A$4746,A25,період!$B$2:$B$4746,B25,період!$C$2:$C$4746,C25,період!$D$2:$D$4746,$D$1) -> 234.4 | E25: =SUMIFS(період!$E$2:$E$4746,період!$A$2:$A$4746,A25,період!$B$2:$B$4746,B25,період!$C$2:$C$4746,C25,період!$D$2:$D$4746,$E$1) -> 211.4 | F25: =IFERROR(D25/E25-"1","") -> 0.10879849 | H25: =IF(F25>0.001,A25,"") -> Чернігівська | I25: =IF(F25>0.001,F25,"") -> 0.10879849 | L25: 47.3 | M25: 24.6 | N25: 22.7 | O25: 21.9 | Q25: 45.7 | R25: 23.8
C27: больше 10 тис. т | D27: меньше 10 тис. т | E27: н/д

Sheet осг
A1: Територіальний розріз | B1: Розріз | C1: Вид господарства | D1: =Лист1!B$16 -> Січ.-вер. 2026 | E1: =Лист1!B$18 -> Січ.-вер. 2025 | F1: =Лист1!J$1 -> 26/25 | H1: Ріст по областям | J1: =COUNTIF(F2:F25,">0") -> 0
A2: Вінницька | B2: Молоко | C2: Господарства населення | D2: =SUMIFS(період!$E$2:$E$4746,період!$A$2:$A$4746,A2,період!$B$2:$B$4746,B2,період!$C$2:$C$4746,C2,період!$D$2:$D$4746,$D$1) -> 191.3 | E2: =SUMIFS(період!$E$2:$E$4746,період!$A$2:$A$4746,A2,період!$B$2:$B$4746,B2,період!$C$2:$C$4746,C2,період!$D$2:$D$4746,$E$1) -> 218.9 | F2: =(D2/E2)-1 -> -0.12608497 | H2: =IF(F2>0,A2,"") | I2: =IF(F2>0,F2,"")
A3: Волинська | B3: Молоко | C3: Господарства населення | D3: =SUMIFS(період!$E$2:$E$4746,період!$A$2:$A$4746,A3,період!$B$2:$B$4746,B3,період!$C$2:$C$4746,C3,період!$D$2:$D$4746,$D$1) -> 94.4 | E3: =SUMIFS(період!$E$2:$E$4746,період!$A$2:$A$4746,A3,період!$B$2:$B$4746,B3,період!$C$2:$C$4746,C3,період!$D$2:$D$4746,$E$1) -> 122.9 | F3: =(D3/E3)-1 -> -0.23189585 | H3: =IF(F3>0,A3,"") | I3: =IF(F3>0,F3,"")
A4: Дніпропетровська | B4: Молоко | C4: Господарства населення | D4: =SUMIFS(період!$E$2:$E$4746,період!$A$2:$A$4746,A4,період!$B$2:$B$4746,B4,період!$C$2:$C$4746,C4,період!$D$2:$D$4746,$D$1) -> 85.1 | E4: =SUMIFS(період!$E$2:$E$4746,період!$A$2:$A$4746,A4,період!$B$2:$B$4746,B4,період!$C$2:$C$4746,C4,період!$D$2:$D$4746,$E$1) -> 101.7 | F4: =(D4/E4)-1 -> -0.16322517 | H4: =IF(F4>0,A4,"") | I4: =IF(F4>0,F4,"")
A5: Донецька | B5: Молоко | C5: Господарства населення | D5: =SUMIFS(період!$E$2:$E$4746,період!$A$2:$A$4746,A5,період!$B$2:$B$4746,B5,період!$C$2:$C$4746,C5,період!$D$2:$D$4746,$D$1) -> 0 | E5: =SUMIFS(період!$E$2:$E$4746,період!$A$2:$A$4746,A5,період!$B$2:$B$4746,B5,період!$C$2:$C$4746,C5,період!$D$2:$D$4746,$E$1) -> 0 | F5: =IFERROR((D5/E5)-1,0) -> 0 | H5: =IF(F5>0,A5,"") | I5: =IF(F5>0,F5,"")
A6: Житомирська | B6: Молоко | C6: Господарства населення | D6: =SUMIFS(період!$E$2:$E$4746,період!$A$2:$A$4746,A6,період!$B$2:$B$4746,B6,період!$C$2:$C$4746,C6,період!$D$2:$D$4746,$D$1) -> 119.3 | E6: =SUMIFS(період!$E$2:$E$4746,період!$A$2:$A$4746,A6,період!$B$2:$B$4746,B6,період!$C$2:$C$4746,C6,період!$D$2:$D$4746,$E$1) -> 193.2 | F6: =(D6/E6)-1 -> -0.38250518 | H6: =IF(F6>0,A6,"") | I6: =IF(F6>0,F6,"")
A7: Закарпатська | B7: Молоко | C7: Господарства населення | D7: =SUMIFS(період!$E$2:$E$4746,період!$A$2:$A$4746,A7,період!$B$2:$B$4746,B7,період!$C$2:$C$4746,C7,період!$D$2:$D$4746,$D$1) -> 58.3 | E7: =SUMIFS(період!$E$2:$E$4746,період!$A$2:$A$4746,A7,період!$B$2:$B$4746,B7,період!$C$2:$C$4746,C7,період!$D$2:$D$4746,$E$1) -> 160.2 | F7: =(D7/E7)-1 -> -0.6360799 | H7: =IF(F7>0,A7,"") | I7: =IF(F7>0,F7,"")
A8: Запорізька | B8: Молоко | C8: Господарства населення | D8: =SUMIFS(період!$E$2:$E$4746,період!$A$2:$A$4746,A8,період!$B$2:$B$4746,B8,період!$C$2:$C$4746,C8,період!$D$2:$D$4746,$D$1) -> 6.9 | E8: =SUMIFS(період!$E$2:$E$4746,період!$A$2:$A$4746,A8,період!$B$2:$B$4746,B8,період!$C$2:$C$4746,C8,період!$D$2:$D$4746,$E$1) -> 10.5 | F8: =(D8/E8)-1 -> -0.34285714 | H8: =IF(F8>0,A8,"") | I8: =IF(F8>0,F8,"")
A9: Івано-Франківська | B9: Молоко | C9: Господарства населення | D9: =SUMIFS(період!$E$2:$E$4746,період!$A$2:$A$4746,A9,період!$B$2:$B$4746,B9,період!$C$2:$C$4746,C9,період!$D$2:$D$4746,$D$1) -> 127.9 | E9: =SUMIFS(період!$E$2:$E$4746,період!$A$2:$A$4746,A9,період!$B$2:$B$4746,B9,період!$C$2:$C$4746,C9,період!$D$2:$D$4746,$E$1) -> 167.6 | F9: =(D9/E9)-1 -> -0.23687351 | H9: =IF(F9>0,A9,"") | I9: =IF(F9>0,F9,"")
A10: Київська | B10: Молоко | C10: Господарства населення | D10: =SUMIFS(період!$E$2:$E$4746,період!$A$2:$A$4746,A10,період!$B$2:$B$4746,B10,період!$C$2:$C$4746,C10,період!$D$2:$D$4746,$D$1) -> 40.7 | E10: =SUMIFS(період!$E$2:$E$4746,період!$A$2:$A$4746,A10,період!$B$2:$B$4746,B10,період!$C$2:$C$4746,C10,період!$D$2:$D$4746,$E$1) -> 43.5 | F10: =(D10/E10)-1 -> -0.064367816 | H10: =IF(F10>0,A10,"") | I10: =IF(F10>0,F10,"")
A11: Кіровоградська | B11: Молоко | C11: Господарства населення | D11: =SUMIFS(період!$E$2:$E$4746,період!$A$2:$A$4746,A11,період!$B$2:$B$4746,B11,період!$C$2:$C$4746,C11,період!$D$2:$D$4746,$D$1) -> 115.4 | E11: =SUMIFS(період!$E$2:$E$4746,період!$A$2:$A$4746,A11,період!$B$2:$B$4746,B11,період!$C$2:$C$4746,C11,період!$D$2:$D$4746,$E$1) -> 133.9 | F11: =(D11/E11)-1 -> -0.13816281 | H11: =IF(F11>0,A11,"") | I11: =IF(F11>0,F11,"")
A12: Луганська | B12: Молоко | C12: Господарства населення | D12: =SUMIFS(період!$E$2:$E$4746,період!$A$2:$A$4746,A12,період!$B$2:$B$4746,B12,період!$C$2:$C$4746,C12,період!$D$2:$D$4746,$D$1) -> 0 | E12: =SUMIFS(період!$E$2:$E$4746,період!$A$2:$A$4746,A12,період!$B$2:$B$4746,B12,період!$C$2:$C$4746,C12,період!$D$2:$D$4746,$E$1) -> 0 | F12: =IFERROR((D12/E12)-1,0) -> 0 | H12: =IF(F12>0,A12,"") | I12: =IF(F12>0,F12,"")
A13: Львівська | B13: Молоко | C13: Господарства населення | D13: =SUMIFS(період!$E$2:$E$4746,період!$A$2:$A$4746,A13,період!$B$2:$B$4746,B13,період!$C$2:$C$4746,C13,період!$D$2:$D$4746,$D$1) -> 130.7 | E13: =SUMIFS(період!$E$2:$E$4746,період!$A$2:$A$4746,A13,період!$B$2:$B$4746,B13,період!$C$2:$C$4746,C13,період!$D$2:$D$4746,$E$1) -> 192.3 | F13: =(D13/E13)-1 -> -0.32033281 | H13: =IF(F13>0,A13,"") | I13: =IF(F13>0,F13,"")
A14: Миколаївська | B14: Молоко | C14: Господарства населення | D14: =SUMIFS(період!$E$2:$E$4746,період!$A$2:$A$4746,A14,період!$B$2:$B$4746,B14,період!$C$2:$C$4746,C14,період!$D$2:$D$4746,$D$1) -> 83.2 | E14: =SUMIFS(період!$E$2:$E$4746,період!$A$2:$A$4746,A14,період!$B$2:$B$4746,B14,період!$C$2:$C$4746,C14,період!$D$2:$D$4746,$E$1) -> 95.6 | F14: =(D14/E14)-1 -> -0.12970711 | H14: =IF(F14>0,A14,"") | I14: =IF(F14>0,F14,"")
A15: Одеська | B15: Молоко | C15: Господарства населення | D15: =SUMIFS(період!$E$2:$E$4746,період!$A$2:$A$4746,A15,період!$B$2:$B$4746,B15,період!$C$2:$C$4746,C15,період!$D$2:$D$4746,$D$1) -> 192 | E15: =SUMIFS(період!$E$2:$E$4746,період!$A$2:$A$4746,A15,період!$B$2:$B$4746,B15,період!$C$2:$C$4746,C15,період!$D$2:$D$4746,$E$1) -> 199.2 | F15: =(D15/E15)-1 -> -0.036144578 | H15: =IF(F15>0,A15,"") | I15: =IF(F15>0,F15,"")
A16: Полтавська | B16: Молоко | C16: Господарства населення | D16: =SUMIFS(період!$E$2:$E$4746,період!$A$2:$A$4746,A16,період!$B$2:$B$4746,B16,період!$C$2:$C$4746,C16,період!$D$2:$D$4746,$D$1) -> 119.4 | E16: =SUMIFS(період!$E$2:$E$4746,період!$A$2:$A$4746,A16,період!$B$2:$B$4746,B16,період!$C$2:$C$4746,C16,період!$D$2:$D$4746,$E$1) -> 150.7 | F16: =(D16/E16)-1 -> -0.20769741 | H16: =IF(F16>0,A16,"") | I16: =IF(F16>0,F16,"")
A17: Рівненська | B17: Молоко | C17: Господарства населення | D17: =SUMIFS(період!$E$2:$E$4746,період!$A$2:$A$4746,A17,період!$B$2:$B$4746,B17,період!$C$2:$C$4746,C17,період!$D$2:$D$4746,$D$1) -> 110.5 | E17: =SUMIFS(період!$E$2:$E$4746,період!$A$2:$A$4746,A17,період!$B$2:$B$4746,B17,період!$C$2:$C$4746,C17,період!$D$2:$D$4746,$E$1) -> 150.5 | F17: =(D17/E17)-1 -> -0.26578073 | H17: =IF(F17>0,A17,"") | I17: =IF(F17>0,F17,"")
A18: Сумська | B18: Молоко | C18: Господарства населення | D18: =SUMIFS(період!$E$2:$E$4746,період!$A$2:$A$4746,A18,період!$B$2:$B$4746,B18,період!$C$2:$C$4746,C18,період!$D$2:$D$4746,$D$1) -> 49.2 | E18: =SUMIFS(період!$E$2:$E$4746,період!$A$2:$A$4746,A18,період!$B$2:$B$4746,B18,період!$C$2:$C$4746,C18,період!$D$2:$D$4746,$E$1) -> 68 | F18: =(D18/E18)-1 -> -0.27647059 | H18: =IF(F18>0,A18,"") | I18: =IF(F18>0,F18,"")
A19: Тернопільська | B19: Молоко | C19: Господарства населення | D19: =SUMIFS(період!$E$2:$E$4746,період!$A$2:$A$4746,A19,період!$B$2:$B$4746,B19,період!$C$2:$C$4746,C19,період!$D$2:$D$4746,$D$1) -> 111.2 | E19: =SUMIFS(період!$E$2:$E$4746,період!$A$2:$A$4746,A19,період!$B$2:$B$4746,B19,період!$C$2:$C$4746,C19,період!$D$2:$D$4746,$E$1) -> 225.4 | F19: =(D19/E19)-1 -> -0.50665484 | H19: =IF(F19>0,A19,"") | I19: =IF(F19>0,F19,"")
A20: Харківська | B20: Молоко | C20: Господарства населення | D20: =SUMIFS(період!$E$2:$E$4746,період!$A$2:$A$4746,A20,період!$B$2:$B$4746,B20,період!$C$2:$C$4746,C20,період!$D$2:$D$4746,$D$1) -> 49.8 | E20: =SUMIFS(період!$E$2:$E$4746,період!$A$2:$A$4746,A20,період!$B$2:$B$4746,B20,період!$C$2:$C$4746,C20,період!$D$2:$D$4746,$E$1) -> 53.2 | F20: =(D20/E20)-1 -> -0.063909774 | H20: =IF(F20>0,A20,"") | I20: =IF(F20>0,F20,"")
A21: Херсонська | B21: Молоко | C21: Господарства населення | D21: =SUMIFS(період!$E$2:$E$4746,період!$A$2:$A$4746,A21,період!$B$2:$B$4746,B21,період!$C$2:$C$4746,C21,період!$D$2:$D$4746,$D$1) -> 0 | E21: =SUMIFS(період!$E$2:$E$4746,період!$A$2:$A$4746,A21,період!$B$2:$B$4746,B21,період!$C$2:$C$4746,C21,період!$D$2:$D$4746,$E$1) -> 0 | F21: =IFERROR((D21/E21)-1,0) -> 0 | H21: =IF(F21>0,A21,"") | I21: =IF(F21>0,F21,"")
A22: Хмельницька | B22: Молоко | C22: Господарства населення | D22: =SUMIFS(період!$E$2:$E$4746,період!$A$2:$A$4746,A22,період!$B$2:$B$4746,B22,період!$C$2:$C$4746,C22,період!$D$2:$D$4746,$D$1) -> 196.7 | E22: =SUMIFS(період!$E$2:$E$4746,період!$A$2:$A$4746,A22,період!$B$2:$B$4746,B22,період!$C$2:$C$4746,C22,період!$D$2:$D$4746,$E$1) -> 276.5 | F22: =(D22/E22)-1 -> -0.28860759 | H22: =IF(F22>0,A22,"") | I22: =IF(F22>0,F22,"")
A23: Черкаська | B23: Молоко | C23: Господарства населення | D23: =SUMIFS(період!$E$2:$E$4746,період!$A$2:$A$4746,A23,період!$B$2:$B$4746,B23,період!$C$2:$C$4746,C23,період!$D$2:$D$4746,$D$1) -> 50.1 | E23: =SUMIFS(період!$E$2:$E$4746,період!$A$2:$A$4746,A23,період!$B$2:$B$4746,B23,період!$C$2:$C$4746,C23,період!$D$2:$D$4746,$E$1) -> 57.9 | F23: =(D23/E23)-1 -> -0.13471503 | H23: =IF(F23>0,A23,"") | I23: =IF(F23>0,F23,"")
A24: Чернівецька | B24: Молоко | C24: Господарства населення | D24: =SUMIFS(період!$E$2:$E$4746,період!$A$2:$A$4746,A24,період!$B$2:$B$4746,B24,період!$C$2:$C$4746,C24,період!$D$2:$D$4746,$D$1) -> 73.7 | E24: =SUMIFS(період!$E$2:$E$4746,період!$A$2:$A$4746,A24,період!$B$2:$B$4746,B24,період!$C$2:$C$4746,C24,період!$D$2:$D$4746,$E$1) -> 110 | F24: =(D24/E24)-1 -> -0.33 | H24: =IF(F24>0,A24,"") | I24: =IF(F24>0,F24,"")
A25: Чернігівська | B25: Молоко | C25: Господарства населення | D25: =SUMIFS(період!$E$2:$E$4746,період!$A$2:$A$4746,A25,період!$B$2:$B$4746,B25,період!$C$2:$C$4746,C25,період!$D$2:$D$4746,$D$1) -> 93.5 | E25: =SUMIFS(період!$E$2:$E$4746,період!$A$2:$A$4746,A25,період!$B$2:$B$4746,B25,період!$C$2:$C$4746,C25,період!$D$2:$D$4746,$E$1) -> 101.7 | F25: =(D25/E25)-1 -> -0.080629302 | H25: =IF(F25>0,A25,"") | I25: =IF(F25>0,F25,"")

Sheet р. усі
A1: Господарства усіх категорій | B1: Надій, тис. гол. | C1: Рейтинг | D1: Загальний, тис. т | E1: =SUM(B2:B25) -> 4612 | F1: Топ, тис. т | G1: =SUMIFS(B2:B25,C2:C25,"<=6") -> 2292.1 | H1: =G1/E1*100% -> 0.49698612
A2: Полтавська | B2: =SUMIFS(усі!D16:D39,усі!A16:A39,A2) -> 476.7 | C2: =RANK(B2,$B$2:$B$25,0) -> 1
A3: Хмельницька | B3: =SUMIFS(усі!D22:D45,усі!A22:A45,A3) -> 433 | C3: =RANK(B3,$B$2:$B$25,0) -> 2
A4: Вінницька | B4: =SUMIFS(усі!D2:D25,усі!A2:A25,A4) -> 414.4 | C4: =RANK(B4,$B$2:$B$25,0) -> 3
A5: Черкаська | B5: =SUMIFS(усі!D23:D46,усі!A23:A46,A5) -> 348.8 | C5: =RANK(B5,$B$2:$B$25,0) -> 4
A6: Чернігівська | B6: =SUMIFS(усі!D25:D48,усі!A25:A48,A6) -> 327.9 | C6: =RANK(B6,$B$2:$B$25,0) -> 5
A7: Тернопільська | B7: =SUMIFS(усі!D19:D42,усі!A19:A42,A7) -> 291.3 | C7: =RANK(B7,$B$2:$B$25,0) -> 6
A8: Київська | B8: =SUMIFS(усі!D10:D33,усі!A10:A33,A8) -> 255.7 | C8: =RANK(B8,$B$2:$B$25,0) -> 7
A9: Житомирська | B9: =SUMIFS(усі!D6:D29,усі!A6:A29,A9) -> 248.5 | C9: =RANK(B9,$B$2:$B$25,0) -> 8
A10: Одеська | B10: =SUMIFS(усі!D15:D38,усі!A15:A38,A10) -> 207.6 | C10: =RANK(B10,$B$2:$B$25,0) -> 9
A11: Волинська | B11: =SUMIFS(усі!D3:D26,усі!A3:A26,A11) -> 189.1 | C11: =RANK(B11,$B$2:$B$25,0) -> 10
A12: Харківська | B12: =SUMIFS(усі!D20:D43,усі!A20:A43,A12) -> 168.4 | C12: =RANK(B12,$B$2:$B$25,0) -> 13
A13: Кіровоградська | B13: =SUMIFS(усі!D11:D34,усі!A11:A34,A13) -> 176 | C13: =RANK(B13,$B$2:$B$25,0) -> 11
A14: Рівненська | B14: =SUMIFS(усі!D17:D40,усі!A17:A40,A14) -> 173.3 | C14: =RANK(B14,$B$2:$B$25,0) -> 12
A15: Львівська | B15: =SUMIFS(усі!D13:D36,усі!A13:A36,A15) -> 160 | C15: =RANK(B15,$B$2:$B$25,0) -> 14
A16: Сумська | B16: =SUMIFS(усі!D18:D41,усі!A18:A41,A16) -> 149.4 | C16: =RANK(B16,$B$2:$B$25,0) -> 15
A17: Миколаївська | B17: =SUMIFS(усі!D14:D37,усі!A14:A37,A17) -> 140.8 | C17: =RANK(B17,$B$2:$B$25,0) -> 17
A18: Івано-Франківська | B18: =SUMIFS(усі!D9:D32,усі!A9:A32,A18) -> 142.5 | C18: =RANK(B18,$B$2:$B$25,0) -> 16
A19: Дніпропетровська | B19: =SUMIFS(усі!D4:D27,усі!A4:A27,A19) -> 125.8 | C19: =RANK(B19,$B$2:$B$25,0) -> 18
A20: Чернівецька | B20: =SUMIFS(усі!D24:D47,усі!A24:A47,A20) -> 78.7 | C20: =RANK(B20,$B$2:$B$25,0) -> 19
A21: Закарпатська | B21: =SUMIFS(усі!D7:D30,усі!A7:A30,A21) -> 59.2 | C21: =RANK(B21,$B$2:$B$25,0) -> 20
A22: Херсонська | B22: =SUMIFS(усі!D21:D44,усі!A21:A44,A22) -> 31.8 | C22: =RANK(B22,$B$2:$B$25,0) -> 21
A23: Запорізька | B23: =SUMIFS(усі!D8:D31,усі!A8:A31,A23) -> 8.6 | C23: =RANK(B23,$B$2:$B$25,0) -> 22
A24: Донецька | B24: =SUMIFS(усі!D5:D28,усі!A5:A28,A24) -> 4.5 | C24: =RANK(B24,$B$2:$B$25,0) -> 23
A25: Луганська | B25: =SUMIFS(усі!D12:D35,усі!A12:A35,A25) -> 0 | C25: =RANK(B25,$B$2:$B$25,0) -> 24

Sheet р. мтф
A1: Господарства усіх категорій | B1: Надій, тис. гол. | C1: Рейтинг | D1: Загальний, тис. т | E1: =SUM(B2:B25) -> 2476.4 | F1: Топ, тис. т | G1: =SUMIFS(B2:B25,C2:C25,"<=5") -> 1349.8 | H1: =G1/E1*100% -> 0.54506542
A2: Полтавська | B2: =SUMIFS(мтф!D16:D39,мтф!A16:A39,A2) -> 357.3 | C2: =RANK(B2,$B$2:$B$25,0) -> 1
A3: Черкаська | B3: =SUMIFS(мтф!D23:D46,мтф!A23:A46,A3) -> 298.7 | C3: =RANK(B3,$B$2:$B$25,0) -> 2
A4: Хмельницька | B4: =SUMIFS(мтф!D22:D45,мтф!A22:A45,A4) -> 236.3 | C4: =RANK(B4,$B$2:$B$25,0) -> 3
A5: Чернігівська | B5: =SUMIFS(мтф!D25:D48,мтф!A25:A48,A5) -> 234.4 | C5: =RANK(B5,$B$2:$B$25,0) -> 4
A6: Вінницька | B6: =SUMIFS(мтф!D2:D25,мтф!A2:A25,A6) -> 223.1 | C6: =RANK(B6,$B$2:$B$25,0) -> 5
A7: Київська | B7: =SUMIFS(мтф!D10:D33,мтф!A10:A33,A7) -> 215 | C7: =RANK(B7,$B$2:$B$25,0) -> 6
A8: Тернопільська | B8: =SUMIFS(мтф!D19:D42,мтф!A19:A42,A8) -> 180.1 | C8: =RANK(B8,$B$2:$B$25,0) -> 7
A9: Житомирська | B9: =SUMIFS(мтф!D6:D29,мтф!A6:A29,A9) -> 129.2 | C9: =RANK(B9,$B$2:$B$25,0) -> 8
A10: Харківська | B10: =SUMIFS(мтф!D20:D43,мтф!A20:A43,A10) -> 118.6 | C10: =RANK(B10,$B$2:$B$25,0) -> 9
A11: Сумська | B11: =SUMIFS(мтф!D18:D41,мтф!A18:A41,A11) -> 100.2 | C11: =RANK(B11,$B$2:$B$25,0) -> 10
A12: Волинська | B12: =SUMIFS(мтф!D3:D26,мтф!A3:A26,A12) -> 94.7 | C12: =RANK(B12,$B$2:$B$25,0) -> 11
A13: Рівненська | B13: =SUMIFS(мтф!D17:D40,мтф!A17:A40,A13) -> 62.8 | C13: =RANK(B13,$B$2:$B$25,0) -> 12
A14: Кіровоградська | B14: =SUMIFS(мтф!D11:D34,мтф!A11:A34,A14) -> 60.6 | C14: =RANK(B14,$B$2:$B$25,0) -> 13
A15: Миколаївська | B15: =SUMIFS(мтф!D14:D37,мтф!A14:A37,A15) -> 57.6 | C15: =RANK(B15,$B$2:$B$25,0) -> 14
A16: Дніпропетровська | B16: =SUMIFS(мтф!D4:D27,мтф!A4:A27,A16) -> 40.7 | C16: =RANK(B16,$B$2:$B$25,0) -> 15
A17: Львівська | B17: =SUMIFS(мтф!D13:D36,мтф!A13:A36,A17) -> 29.3 | C17: =RANK(B17,$B$2:$B$25,0) -> 16
A18: Одеська | B18: =SUMIFS(мтф!D15:D38,мтф!A15:A38,A18) -> 15.6 | C18: =RANK(B18,$B$2:$B$25,0) -> 17
A19: Івано-Франківська | B19: =SUMIFS(мтф!D9:D32,мтф!A9:A32,A19) -> 14.6 | C19: =RANK(B19,$B$2:$B$25,0) -> 18
A20: Чернівецька | B20: =SUMIFS(мтф!D24:D47,мтф!A24:A47,A20) -> 5 | C20: =RANK(B20,$B$2:$B$25,0) -> 19
A21: Запорізька | B21: =SUMIFS(мтф!D8:D31,мтф!A8:A31,A21) -> 1.7 | C21: =RANK(B21,$B$2:$B$25,0) -> 20
A22: Закарпатська | B22: =SUMIFS(мтф!D7:D30,мтф!A7:A30,A22) -> 0.9 | C22: =RANK(B22,$B$2:$B$25,0) -> 21
A23: Донецька | B23: =SUMIFS(мтф!D5:D28,мтф!A5:A28,A23) -> 0 | C23: =RANK(B23,$B$2:$B$25,0) -> 22
A24: Луганська | B24: =SUMIFS(мтф!D12:D35,мтф!A12:A35,A24) -> 0 | C24: =RANK(B24,$B$2:$B$25,0) -> 22
A25: Херсонська | B25: =SUMIFS(мтф!D21:D44,мтф!A21:A44,A25) -> 0 | C25: =RANK(B25,$B$2:$B$25,0) -> 22

Sheet діаграма
B1: =Лист1!D$1 -> 46266 | C1: =Лист1!E$1 -> 46235 | D1: =Лист1!F$1 -> 45901
A2: С-г підприємства | B2: =Лист1!D3 -> 266.4 | C2: =Лист1!E3 -> 275.7 | D2: =Лист1!F3 -> 278.8
A3: Господарства населення | B3: =Лист1!D4 -> 243 | C3: =Лист1!E4 -> 268 | D3: =Лист1!F4 -> 334
A8: Джерело: Аналітичний відділ АВМ за попередніми даними Держстату*, **
A9: *Дані наведено без урахування тимчасово окупованих російською федерацією територій та частини територій, на яких ведуться (велися) бойові дії.
A10: **Донецька, Луганська, Херсонська -- дані не оприлюднюються згідно вимог ЗУ «Про офіційну статистику».
